<?xml version="1.0" encoding="UTF-8"?>
<!-- Generated by org.testng.reporters.JUnitReportReporter -->
<testsuite hostname="DESKTOP-LT0MAOO" name="Org.qsp.testgdemo.demoassert" tests="3" failures="1" timestamp="29 Jul 2020 04:51:09 GMT" time="0.020" errors="1">
  <testcase name="m3" time="0.005" classname="Org.qsp.testgdemo.demoassert"/>
  <testcase name="m1" time="0.000" classname="Org.qsp.testgdemo.demoassert">
    <error type="java.lang.Throwable" message="Method demoassert.m1()[pri:0, instance:Org.qsp.testgdemo.demoassert@51081592] depends on not successfully finished methods">
      <![CDATA[java.lang.Throwable: Method demoassert.m1()[pri:0, instance:Org.qsp.testgdemo.demoassert@51081592] depends on not successfully finished methods
	at org.testng.internal.Invoker.invokeTestMethods(Invoker.java:1028)
	at org.testng.internal.TestMethodWorker.invokeTestMethods(TestMethodWorker.java:129)
	at org.testng.internal.TestMethodWorker.run(TestMethodWorker.java:112)
	at org.testng.TestRunner.privateRun(TestRunner.java:746)
	at org.testng.TestRunner.run(TestRunner.java:600)
	at org.testng.SuiteRunner.runTest(SuiteRunner.java:366)
	at org.testng.SuiteRunner.runSequentially(SuiteRunner.java:361)
	at org.testng.SuiteRunner.privateRun(SuiteRunner.java:319)
	at org.testng.SuiteRunner.run(SuiteRunner.java:268)
	at org.testng.SuiteRunnerWorker.runSuite(SuiteRunnerWorker.java:52)
	at org.testng.SuiteRunnerWorker.run(SuiteRunnerWorker.java:86)
	at org.testng.TestNG.runSuitesSequentially(TestNG.java:1264)
	at org.testng.TestNG.runSuitesLocally(TestNG.java:1189)
	at org.testng.TestNG.runSuites(TestNG.java:1104)
	at org.testng.TestNG.run(TestNG.java:1076)
	at org.testng.remote.AbstractRemoteTestNG.run(AbstractRemoteTestNG.java:126)
	at org.testng.remote.RemoteTestNG.initAndRun(RemoteTestNG.java:152)
	at org.testng.remote.RemoteTestNG.main(RemoteTestNG.java:57)
]]>
    </error>
  </testcase> <!-- m1 -->
  <testcase name="m2" time="0.015" classname="Org.qsp.testgdemo.demoassert">
    <failure type="java.lang.AssertionError" message="null">
      <![CDATA[java.lang.AssertionError: null
	at org.testng.Assert.fail(Assert.java:94)
	at org.testng.Assert.fail(Assert.java:101)
	at Org.qsp.testgdemo.demoassert.m2(demoassert.java:17)
	at sun.reflect.NativeMethodAccessorImpl.invoke0(Native Method)
	at sun.reflect.NativeMethodAccessorImpl.invoke(NativeMethodAccessorImpl.java:62)
	at sun.reflect.DelegatingMethodAccessorImpl.invoke(DelegatingMethodAccessorImpl.java:43)
	at java.lang.reflect.Method.invoke(Method.java:498)
	at org.testng.internal.MethodInvocationHelper.invokeMethod(MethodInvocationHelper.java:100)
	at org.testng.internal.Invoker.invokeMethod(Invoker.java:646)
	at org.testng.internal.Invoker.invokeTestMethod(Invoker.java:811)
	at org.testng.internal.Invoker.invokeTestMethods(Invoker.java:1129)
	at org.testng.internal.TestMethodWorker.invokeTestMethods(TestMethodWorker.java:129)
	at org.testng.internal.TestMethodWorker.run(TestMethodWorker.java:112)
	at org.testng.TestRunner.privateRun(TestRunner.java:746)
	at org.testng.TestRunner.run(TestRunner.java:600)
	at org.testng.SuiteRunner.runTest(SuiteRunner.java:366)
	at org.testng.SuiteRunner.runSequentially(SuiteRunner.java:361)
	at org.testng.SuiteRunner.privateRun(SuiteRunner.java:319)
	at org.testng.SuiteRunner.run(SuiteRunner.java:268)
	at org.testng.SuiteRunnerWorker.runSuite(SuiteRunnerWorker.java:52)
	at org.testng.SuiteRunnerWorker.run(SuiteRunnerWorker.java:86)
	at org.testng.TestNG.runSuitesSequentially(TestNG.java:1264)
	at org.testng.TestNG.runSuitesLocally(TestNG.java:1189)
	at org.testng.TestNG.runSuites(TestNG.java:1104)
	at org.testng.TestNG.run(TestNG.java:1076)
	at org.testng.remote.AbstractRemoteTestNG.run(AbstractRemoteTestNG.java:126)
	at org.testng.remote.RemoteTestNG.initAndRun(RemoteTestNG.java:152)
	at org.testng.remote.RemoteTestNG.main(RemoteTestNG.java:57)
]]>
    </failure>
  </testcase> <!-- m2 -->
</testsuite> <!-- Org.qsp.testgdemo.demoassert -->
